ERROR:django.request: Internal Server Error: /your_tasks/ (2018-07-06 16:44:13; exception.py:135)
Traceback (most recent call last):
  File "/Library/Python/2.7/site-packages/django/core/handlers/exception.py", line 41, in inner
    response = get_response(request)
  File "/Library/Python/2.7/site-packages/django/core/handlers/base.py", line 187, in _get_response
    response = self.process_exception_by_middleware(e, request)
  File "/Library/Python/2.7/site-packages/django/core/handlers/base.py", line 185, in _get_response
    response = wrapped_callback(request, *callback_args, **callback_kwargs)
  File "/Library/Python/2.7/site-packages/django/views/generic/base.py", line 68, in view
    return self.dispatch(request, *args, **kwargs)
  File "/Library/Python/2.7/site-packages/django/views/generic/base.py", line 88, in dispatch
    return handler(request, *args, **kwargs)
  File "/Library/Python/2.7/site-packages/django/views/generic/list.py", line 159, in get
    self.object_list = self.get_queryset()
  File "/Library/Python/2.7/site-packages/django/utils/decorators.py", line 185, in inner
    return func(*args, **kwargs)
  File "/Users/arthuratrokhov/Desktop/python/freelance/exchange/views.py", line 88, in get_queryset
    return Notice.objects.filter(executor=self.request.user)
  File "/Library/Python/2.7/site-packages/django/db/models/manager.py", line 85, in manager_method
    return getattr(self.get_queryset(), name)(*args, **kwargs)
  File "/Library/Python/2.7/site-packages/django/db/models/query.py", line 781, in filter
    return self._filter_or_exclude(False, *args, **kwargs)
  File "/Library/Python/2.7/site-packages/django/db/models/query.py", line 799, in _filter_or_exclude
    clone.query.add_q(Q(*args, **kwargs))
  File "/Library/Python/2.7/site-packages/django/db/models/sql/query.py", line 1260, in add_q
    clause, _ = self._add_q(q_object, self.used_aliases)
  File "/Library/Python/2.7/site-packages/django/db/models/sql/query.py", line 1286, in _add_q
    allow_joins=allow_joins, split_subq=split_subq,
  File "/Library/Python/2.7/site-packages/django/db/models/sql/query.py", line 1189, in build_filter
    self.check_related_objects(field, value, opts)
  File "/Library/Python/2.7/site-packages/django/db/models/sql/query.py", line 1088, in check_related_objects
    for v in value:
  File "/Library/Python/2.7/site-packages/django/utils/functional.py", line 239, in inner
    return func(self._wrapped, *args)
TypeError: 'AnonymousUser' object is not iterable
ERROR:django.request: Internal Server Error: /your_tasks/ (2018-07-06 16:45:11; exception.py:135)
Traceback (most recent call last):
  File "/Library/Python/2.7/site-packages/django/core/handlers/exception.py", line 41, in inner
    response = get_response(request)
  File "/Library/Python/2.7/site-packages/django/core/handlers/base.py", line 187, in _get_response
    response = self.process_exception_by_middleware(e, request)
  File "/Library/Python/2.7/site-packages/django/core/handlers/base.py", line 185, in _get_response
    response = wrapped_callback(request, *callback_args, **callback_kwargs)
  File "/Library/Python/2.7/site-packages/django/views/generic/base.py", line 68, in view
    return self.dispatch(request, *args, **kwargs)
  File "/Library/Python/2.7/site-packages/django/views/generic/base.py", line 88, in dispatch
    return handler(request, *args, **kwargs)
  File "/Library/Python/2.7/site-packages/django/views/generic/list.py", line 159, in get
    self.object_list = self.get_queryset()
  File "/Library/Python/2.7/site-packages/django/utils/decorators.py", line 185, in inner
    return func(*args, **kwargs)
  File "/Users/arthuratrokhov/Desktop/python/freelance/exchange/views.py", line 88, in get_queryset
    return Notice.objects.filter(executor=self.request.user)
  File "/Library/Python/2.7/site-packages/django/db/models/manager.py", line 85, in manager_method
    return getattr(self.get_queryset(), name)(*args, **kwargs)
  File "/Library/Python/2.7/site-packages/django/db/models/query.py", line 781, in filter
    return self._filter_or_exclude(False, *args, **kwargs)
  File "/Library/Python/2.7/site-packages/django/db/models/query.py", line 799, in _filter_or_exclude
    clone.query.add_q(Q(*args, **kwargs))
  File "/Library/Python/2.7/site-packages/django/db/models/sql/query.py", line 1260, in add_q
    clause, _ = self._add_q(q_object, self.used_aliases)
  File "/Library/Python/2.7/site-packages/django/db/models/sql/query.py", line 1286, in _add_q
    allow_joins=allow_joins, split_subq=split_subq,
  File "/Library/Python/2.7/site-packages/django/db/models/sql/query.py", line 1189, in build_filter
    self.check_related_objects(field, value, opts)
  File "/Library/Python/2.7/site-packages/django/db/models/sql/query.py", line 1088, in check_related_objects
    for v in value:
  File "/Library/Python/2.7/site-packages/django/utils/functional.py", line 239, in inner
    return func(self._wrapped, *args)
TypeError: 'AnonymousUser' object is not iterable
ERROR:django.request: Internal Server Error: /your_notices/ (2018-07-06 16:46:52; exception.py:135)
Traceback (most recent call last):
  File "/Library/Python/2.7/site-packages/django/core/handlers/exception.py", line 41, in inner
    response = get_response(request)
  File "/Library/Python/2.7/site-packages/django/core/handlers/base.py", line 187, in _get_response
    response = self.process_exception_by_middleware(e, request)
  File "/Library/Python/2.7/site-packages/django/core/handlers/base.py", line 185, in _get_response
    response = wrapped_callback(request, *callback_args, **callback_kwargs)
  File "/Library/Python/2.7/site-packages/django/views/generic/base.py", line 68, in view
    return self.dispatch(request, *args, **kwargs)
  File "/Library/Python/2.7/site-packages/django/views/generic/base.py", line 88, in dispatch
    return handler(request, *args, **kwargs)
  File "/Library/Python/2.7/site-packages/django/views/generic/list.py", line 159, in get
    self.object_list = self.get_queryset()
  File "/Library/Python/2.7/site-packages/django/utils/decorators.py", line 185, in inner
    return func(*args, **kwargs)
  File "/Users/arthuratrokhov/Desktop/python/freelance/exchange/views.py", line 64, in get_queryset
    return Notice.objects.filter(author=self.request.user)
  File "/Library/Python/2.7/site-packages/django/db/models/manager.py", line 85, in manager_method
    return getattr(self.get_queryset(), name)(*args, **kwargs)
  File "/Library/Python/2.7/site-packages/django/db/models/query.py", line 781, in filter
    return self._filter_or_exclude(False, *args, **kwargs)
  File "/Library/Python/2.7/site-packages/django/db/models/query.py", line 799, in _filter_or_exclude
    clone.query.add_q(Q(*args, **kwargs))
  File "/Library/Python/2.7/site-packages/django/db/models/sql/query.py", line 1260, in add_q
    clause, _ = self._add_q(q_object, self.used_aliases)
  File "/Library/Python/2.7/site-packages/django/db/models/sql/query.py", line 1286, in _add_q
    allow_joins=allow_joins, split_subq=split_subq,
  File "/Library/Python/2.7/site-packages/django/db/models/sql/query.py", line 1189, in build_filter
    self.check_related_objects(field, value, opts)
  File "/Library/Python/2.7/site-packages/django/db/models/sql/query.py", line 1088, in check_related_objects
    for v in value:
  File "/Library/Python/2.7/site-packages/django/utils/functional.py", line 239, in inner
    return func(self._wrapped, *args)
TypeError: 'AnonymousUser' object is not iterable
ERROR:django.request: Internal Server Error: /your_notices/ (2018-07-06 16:47:22; exception.py:135)
Traceback (most recent call last):
  File "/Library/Python/2.7/site-packages/django/core/handlers/exception.py", line 41, in inner
    response = get_response(request)
  File "/Library/Python/2.7/site-packages/django/core/handlers/base.py", line 187, in _get_response
    response = self.process_exception_by_middleware(e, request)
  File "/Library/Python/2.7/site-packages/django/core/handlers/base.py", line 185, in _get_response
    response = wrapped_callback(request, *callback_args, **callback_kwargs)
  File "/Library/Python/2.7/site-packages/django/views/generic/base.py", line 68, in view
    return self.dispatch(request, *args, **kwargs)
  File "/Library/Python/2.7/site-packages/django/views/generic/base.py", line 88, in dispatch
    return handler(request, *args, **kwargs)
  File "/Library/Python/2.7/site-packages/django/views/generic/list.py", line 159, in get
    self.object_list = self.get_queryset()
  File "/Library/Python/2.7/site-packages/django/utils/decorators.py", line 185, in inner
    return func(*args, **kwargs)
  File "/Users/arthuratrokhov/Desktop/python/freelance/exchange/views.py", line 64, in get_queryset
    return Notice.objects.filter(author=self.request.user)
  File "/Library/Python/2.7/site-packages/django/db/models/manager.py", line 85, in manager_method
    return getattr(self.get_queryset(), name)(*args, **kwargs)
  File "/Library/Python/2.7/site-packages/django/db/models/query.py", line 781, in filter
    return self._filter_or_exclude(False, *args, **kwargs)
  File "/Library/Python/2.7/site-packages/django/db/models/query.py", line 799, in _filter_or_exclude
    clone.query.add_q(Q(*args, **kwargs))
  File "/Library/Python/2.7/site-packages/django/db/models/sql/query.py", line 1260, in add_q
    clause, _ = self._add_q(q_object, self.used_aliases)
  File "/Library/Python/2.7/site-packages/django/db/models/sql/query.py", line 1286, in _add_q
    allow_joins=allow_joins, split_subq=split_subq,
  File "/Library/Python/2.7/site-packages/django/db/models/sql/query.py", line 1189, in build_filter
    self.check_related_objects(field, value, opts)
  File "/Library/Python/2.7/site-packages/django/db/models/sql/query.py", line 1088, in check_related_objects
    for v in value:
  File "/Library/Python/2.7/site-packages/django/utils/functional.py", line 239, in inner
    return func(self._wrapped, *args)
TypeError: 'AnonymousUser' object is not iterable
